<?xml version="1.0"?>
<!-- 
    This file is the urdf description of an ALDEBARAN robot.
    It has been generated by robot_description tool available in the simulator-sdk.
    For more information about urdf, see http://www.ros.org/wiki/urdf/
 -->


<robot name="nao">
  <link name="base_link" />

  <material name="LightGrey">
    <color rgba="0.9 0.9 0.9 1.0"/>
  </material>
  <link name="torso">
    <visual>
      <origin xyz="0 0 0" rpy="0 -0 0"/>
      <geometry>
        <mesh filename="package://nao_detector/meshes/V32/Torso.mesh" scale="0.001 0.001 0.001"/>
      </geometry>
      <material name="LightGrey"/>
    </visual>
    <inertial>
      <origin xyz="-0.0048 6e-05 0.04227" rpy="0 0 0"/>
      <mass value="1.02628"/>
      <inertia ixx="0.00487953" ixy="1.42859e-05" ixz="0.000195457" iyy="0.00470361" iyz="-2.22459e-05" izz="0.00156714" />
    </inertial>
    <collision>
      <origin xyz="0 0 0" rpy="0 -0 0"/>
      <geometry>
        <mesh filename="package://nao_detector/meshes/V32/Torso.mesh" scale="0.001 0.001 0.001"/>
      </geometry>
      <material name="LightGrey"/>
    </collision>
  </link>
  <link name="HeadYaw_link">
    <visual>
      <origin xyz="0 0 0" rpy="0 -0 0"/>
      <geometry>
        <mesh filename="package://nao_detector/meshes/V32/HeadYaw.mesh" scale="0.001 0.001 0.001"/>
      </geometry>
      <material name="LightGrey"/>
    </visual>
    <inertial>
      <origin xyz="-3e-05 0.00018 -0.02573" rpy="0 0 0"/>
      <mass value="0.05959"/>
      <inertia ixx="6.22337e-05" ixy="-4.2e-10" ixz="-7.448e-08" iyy="6.32443e-05" iyz="-1.0416e-07" izz="5.49462e-06" />
    </inertial>
    <collision>
      <origin xyz="0 0 0" rpy="0 -0 0"/>
      <geometry>
        <mesh filename="package://nao_detector/meshes/V32/HeadYaw.mesh" scale="0.001 0.001 0.001"/>
      </geometry>
      <material name="LightGrey"/>
    </collision>
  </link>
  <link name="HeadPitch_link">
    <visual>
      <origin xyz="0 0 0" rpy="0 -0 0"/>
      <geometry>
        <mesh filename="package://nao_detector/meshes/V32/HeadPitch.mesh" scale="0.001 0.001 0.001"/>
      </geometry>
      <material name="LightGrey"/>
    </visual>
    <inertial>
      <origin xyz="0.05156 0.00383 -0.00093" rpy="0 0 0"/>
      <mass value="0.47672"/>
      <inertia ixx="0.00487953" ixy="1.42859e-05" ixz="0.000195457" iyy="0.00470361" iyz="-2.22459e-05" izz="0.00156714" />
    </inertial>
    <collision>
      <origin xyz="0 0 0" rpy="0 -0 0"/>
      <geometry>
        <mesh filename="package://nao_detector/meshes/V32/HeadPitch.mesh" scale="0.001 0.001 0.001"/>
      </geometry>
      <material name="LightGrey"/>
    </collision>
  </link>
  <link name="LShoulderPitch_link">
    <visual>
      <origin xyz="0 0 0" rpy="0 -0 0"/>
      <geometry>
        <mesh filename="package://nao_detector/meshes/V32/LShoulderPitch.mesh" scale="0.001 0.001 0.001"/>
      </geometry>
      <material name="LightGrey"/>
    </visual>
    <inertial>
      <origin xyz="-0.00178 -0.00019 -0.02507" rpy="0 0 0"/>
      <mass value="0.06984"/>
      <inertia ixx="7.10185e-05" ixy="-2.02458e-06" ixz="1.713e-08" iyy="1.40492e-05" iyz="-4.41e-08" izz="7.31447e-05" />
    </inertial>
    <collision>
      <origin xyz="0 0 0" rpy="0 -0 0"/>
      <geometry>
        <mesh filename="package://nao_detector/meshes/V32/LShoulderPitch.mesh" scale="0.001 0.001 0.001"/>
      </geometry>
      <material name="LightGrey"/>
    </collision>
  </link>
  <link name="LShoulderRoll_link">
    <visual>
      <origin xyz="0 0 0" rpy="0 -0 0"/>
      <geometry>
        <mesh filename="package://nao_detector/meshes/V32/LShoulderRoll.mesh" scale="0.001 0.001 0.001"/>
      </geometry>
      <material name="LightGrey"/>
    </visual>
    <inertial>
      <origin xyz="0.00388 -0.02067 0.00362" rpy="0 0 0"/>
      <mass value="0.12166"/>
      <inertia ixx="5.93179e-05" ixy="-1.93929e-06" ixz="-1.5645e-06" iyy="0.000202211" iyz="-3.68731e-06" izz="0.000184216" />
    </inertial>
    <collision>
      <origin xyz="0 0 0" rpy="0 -0 0"/>
      <geometry>
        <mesh filename="package://nao_detector/meshes/V32/LShoulderRoll.mesh" scale="0.001 0.001 0.001"/>
      </geometry>
      <material name="LightGrey"/>
    </collision>
  </link>
  <link name="LElbowYaw_link">
    <visual>
      <origin xyz="0 0 0" rpy="0 -0 0"/>
      <geometry>
        <mesh filename="package://nao_detector/meshes/V32/LElbowYaw.mesh" scale="0.001 0.001 0.001"/>
      </geometry>
      <material name="LightGrey"/>
    </visual>
    <inertial>
      <origin xyz="-1e-05 -0.0002 -0.02573" rpy="0 0 0"/>
      <mass value="0.05959"/>
      <inertia ixx="5.49462e-06" ixy="-2.242e-08" ixz="6.771e-08" iyy="6.22479e-05" iyz="5.59e-09" izz="6.32301e-05" />
    </inertial>
    <collision>
      <origin xyz="0 0 0" rpy="0 -0 0"/>
      <geometry>
        <mesh filename="package://nao_detector/meshes/V32/LElbowYaw.mesh" scale="0.001 0.001 0.001"/>
      </geometry>
      <material name="LightGrey"/>
    </collision>
  </link>
  <link name="LElbowRoll_link">
    <visual>
      <origin xyz="0 0 0" rpy="0 -0 0"/>
      <geometry>
        <mesh filename="package://nao_detector/meshes/V32/LElbowRoll.mesh" scale="0.001 0.001 0.001"/>
      </geometry>
      <material name="LightGrey"/>
    </visual>
    <inertial>
      <origin xyz="0.00304 -0.0194 0.0025" rpy="0 0 0"/>
      <mass value="0.0377"/>
      <inertia ixx="1.2711e-05" ixy="-1.3146e-06" ixz="-1.43626e-06" iyy="3.0569e-05" iyz="-2.0686e-07" izz="2.97629e-05" />
    </inertial>
    <collision>
      <origin xyz="0 0 0" rpy="0 -0 0"/>
      <geometry>
        <mesh filename="package://nao_detector/meshes/V32/LElbowRoll.mesh" scale="0.001 0.001 0.001"/>
      </geometry>
      <material name="LightGrey"/>
    </collision>
  </link>
  <link name="LWristYaw_link">
    <visual>
      <origin xyz="0 0 0" rpy="0 -0 0"/>
      <geometry>
        <mesh filename="package://nao_detector/meshes/V32/WristYaw.mesh" scale="0.001 0.001 0.001"/>
      </geometry>
      <material name="LightGrey"/>
    </visual>
    <inertial>
      <origin xyz="0.00268 -0.00272 0.03241" rpy="0 0 0"/>
      <mass value="0.14314"/>
      <inertia ixx="5.69262e-05" ixy="-8.22213e-06" ixz="1.13629e-05" iyy="0.000272309" iyz="1.8178e-06" izz="0.000266114" />
    </inertial>
    <collision>
      <origin xyz="0 0 0" rpy="0 -0 0"/>
      <geometry>
        <mesh filename="package://nao_detector/meshes/V32/WristYaw.mesh" scale="0.001 0.001 0.001"/>
      </geometry>
      <material name="LightGrey"/>
    </collision>
  </link>
  
  <link name="RShoulderPitch_link">
    <visual>
      <origin xyz="0 0 0" rpy="0 -0 0"/>
      <geometry>
        <mesh filename="package://nao_detector/meshes/V32/RShoulderPitch.mesh" scale="0.001 0.001 0.001"/>
      </geometry>
      <material name="LightGrey"/>
    </visual>
    <inertial>
      <origin xyz="-0.00178 -0.00019 0.02507" rpy="0 0 0"/>
      <mass value="0.06984"/>
      <inertia ixx="7.10185e-05" ixy="2.02458e-06" ixz="1.713e-08" iyy="1.40492e-05" iyz="4.41e-08" izz="7.31447e-05" />
    </inertial>
    <collision>
      <origin xyz="0 0 0" rpy="0 -0 0"/>
      <geometry>
        <mesh filename="package://nao_detector/meshes/V32/RShoulderPitch.mesh" scale="0.001 0.001 0.001"/>
      </geometry>
      <material name="LightGrey"/>
    </collision>
  </link>
  <link name="RShoulderRoll_link">
    <visual>
      <origin xyz="0 0 0" rpy="0 -0 0"/>
      <geometry>
        <mesh filename="package://nao_detector/meshes/V32/RShoulderRoll.mesh" scale="0.001 0.001 0.001"/>
      </geometry>
      <material name="LightGrey"/>
    </visual>
    <inertial>
      <origin xyz="-0.00388 -0.02067 0.00362" rpy="0 0 0"/>
      <mass value="0.12166"/>
      <inertia ixx="5.93179e-05" ixy="1.93929e-06" ixz="-1.5645e-05" iyy="0.000202211" iyz="3.68731e-06" izz="0.000184216" />
    </inertial>
    <collision>
      <origin xyz="0 0 0" rpy="0 -0 0"/>
      <geometry>
        <mesh filename="package://nao_detector/meshes/V32/RShoulderRoll.mesh" scale="0.001 0.001 0.001"/>
      </geometry>
      <material name="LightGrey"/>
    </collision>
  </link>
  <link name="RElbowYaw_link">
    <visual>
      <origin xyz="0 0 0" rpy="0 -0 0"/>
      <geometry>
        <mesh filename="package://nao_detector/meshes/V32/RElbowYaw.mesh" scale="0.001 0.001 0.001"/>
      </geometry>
      <material name="LightGrey"/>
    </visual>
    <inertial>
      <origin xyz="1e-05 -0.0002 -0.02573" rpy="0 0 0"/>
      <mass value="0.05959"/>
      <inertia ixx="5.49462e-06" ixy="2.242e-08" ixz="6.771e-08" iyy="6.22479e-05" iyz="-5.59e-09" izz="6.32301e-05" />
    </inertial>
    <collision>
      <origin xyz="0 0 0" rpy="0 -0 0"/>
      <geometry>
        <mesh filename="package://nao_detector/meshes/V32/RElbowYaw.mesh" scale="0.001 0.001 0.001"/>
      </geometry>
      <material name="LightGrey"/>
    </collision>
  </link>
  <link name="RElbowRoll_link">
    <visual>
      <origin xyz="0 0 0" rpy="0 -0 0"/>
      <geometry>
        <mesh filename="package://nao_detector/meshes/V32/RElbowRoll.mesh" scale="0.001 0.001 0.001"/>
      </geometry>
      <material name="LightGrey"/>
    </visual>
    <inertial>
      <origin xyz="-0.00304 -0.0194 0.0025" rpy="0 0 0"/>
      <mass value="0.0377"/>
      <inertia ixx="1.2711e-05" ixy="1.3146e-06" ixz="-1.43626e-06" iyy="3.0569e-05" iyz="2.0686e-07" izz="2.97629e-05" />
    </inertial>
    <collision>
      <origin xyz="0 0 0" rpy="0 -0 0"/>
      <geometry>
        <mesh filename="package://nao_detector/meshes/V32/RElbowRoll.mesh" scale="0.001 0.001 0.001"/>
      </geometry>
      <material name="LightGrey"/>
    </collision>
  </link>
  <link name="RWristYaw_link">
    <visual>
      <origin xyz="0 0 0" rpy="0 -0 0"/>
      <geometry>
        <mesh filename="package://nao_detector/meshes/V32/WristYaw.mesh" scale="0.001 0.001 0.001"/>
      </geometry>
      <material name="LightGrey"/>
    </visual>
    <inertial>
      <origin xyz="-0.00268 -0.00272 0.03241" rpy="0 0 0"/>
      <mass value="0.14314"/>
      <inertia ixx="5.69262e-05" ixy="8.22213e-06" ixz="1.13629e-05" iyy="0.000272309" iyz="-1.8178e-06" izz="0.000266114" />
    </inertial>
    <collision>
      <origin xyz="0 0 0" rpy="0 -0 0"/>
      <geometry>
        <mesh filename="package://nao_detector/meshes/V32/WristYaw.mesh" scale="0.001 0.001 0.001"/>
      </geometry>
      <material name="LightGrey"/>
    </collision>
  </link>
  
  
  <link name="LHipYawPitch_link">
    <visual>
      <origin xyz="0 0 0" rpy="0 -0 0"/>
      <geometry>
        <mesh filename="package://nao_detector/meshes/V32/LHipYawPitch.mesh" scale="0.001 0.001 0.001"/>
      </geometry>
      <material name="LightGrey"/>
    </visual>
    <inertial>
      <origin xyz="0.0107339 -0.00717 -0.0275206" rpy="0 0 0"/>
      <mass value="0.07244"/>
      <inertia ixx="9.06449e-05" ixy="-4.88819e-06" ixz="1.22192e-05" iyy="0.000106658" iyz="2.78382e-05" izz="6.74286e-05" />
    </inertial>
    <collision>
      <origin xyz="0 0 0" rpy="0 -0 0"/>
      <geometry>
        <mesh filename="package://nao_detector/meshes/V32/LHipYawPitch.mesh" scale="0.001 0.001 0.001"/>
      </geometry>
      <material name="LightGrey"/>
    </collision>
  </link>
  <link name="LHipRoll_link">
    <visual>
      <origin xyz="0 0 0" rpy="0 -0 0"/>
      <geometry>
        <mesh filename="package://nao_detector/meshes/V32/LHipRoll.mesh" scale="0.001 0.001 0.001"/>
      </geometry>
      <material name="LightGrey"/>
    </visual>
    <inertial>
      <origin xyz="-0.00475 -0.00029 -0.01649" rpy="0 0 0"/>
      <mass value="0.1353"/>
      <inertia ixx="2.79131e-05" ixy="4.982e-08" ixz="-5.30968e-06" iyy="0.000101469" iyz="4.9e-10" izz="0.000292094" />
    </inertial>
    <collision>
      <origin xyz="0 0 0" rpy="0 -0 0"/>
      <geometry>
        <mesh filename="package://nao_detector/meshes/V32/LHipRoll.mesh" scale="0.001 0.001 0.001"/>
      </geometry>
      <material name="LightGrey"/>
    </collision>
  </link>
  <link name="LHipPitch_link">
    <visual>
      <origin xyz="0 0 0" rpy="0 -0 0"/>
      <geometry>
        <mesh filename="package://nao_detector/meshes/V32/LHipPitch.mesh" scale="0.001 0.001 0.001"/>
      </geometry>
      <material name="LightGrey"/>
    </visual>
    <inertial>
      <origin xyz="-0.05386 0.00131 0.00201" rpy="0 0 0"/>
      <mass value="0.39798"/>
      <inertia ixx="0.00166559" ixy="4.3251e-07" ixz="8.25051e-05" iyy="0.001625" iyz="3.17428e-05" izz="0.000304929" />
    </inertial>
    <collision>
      <origin xyz="0 0 0" rpy="0 -0 0"/>
      <geometry>
        <mesh filename="package://nao_detector/meshes/V32/LHipPitch.mesh" scale="0.001 0.001 0.001"/>
      </geometry>
      <material name="LightGrey"/>
    </collision>
  </link>
  <link name="LKneePitch_link">
    <visual>
      <origin xyz="0 0 0" rpy="0 -0 0"/>
      <geometry>
        <mesh filename="package://nao_detector/meshes/V32/LKneePitch.mesh" scale="0.001 0.001 0.001"/>
      </geometry>
      <material name="LightGrey"/>
    </visual>
    <inertial>
      <origin xyz="-0.04891 0.00471 0.0021" rpy="0 0 0"/>
      <mass value="0.29714"/>
      <inertia ixx="0.00118034" ixy="3.0542e-07" ixz="4.0171e-05" iyy="0.00112928" iyz="3.57364e-05" izz="0.00019349" />
    </inertial>
    <collision>
      <origin xyz="0 0 0" rpy="0 -0 0"/>
      <geometry>
        <mesh filename="package://nao_detector/meshes/V32/LKneePitch.mesh" scale="0.001 0.001 0.001"/>
      </geometry>
      <material name="LightGrey"/>
    </collision>
  </link>
  <link name="LAnklePitch_link">
    <visual>
      <origin xyz="0 0 0" rpy="0 -0 0"/>
      <geometry>
        <mesh filename="package://nao_detector/meshes/V32/LAnklePitch.mesh" scale="0.001 0.001 0.001"/>
      </geometry>
      <material name="LightGrey"/>
    </visual>
    <inertial>
      <origin xyz="0.00638 0.00142 0.00028" rpy="0 0 0"/>
      <mass value="0.13892"/>
      <inertia ixx="3.88258e-05" ixy="-4.942e-08" ixz="2.21321e-06" iyy="7.21158e-05" iyz="6.74e-09" izz="5.35199e-05" />
    </inertial>
    <collision>
      <origin xyz="0 0 0" rpy="0 -0 0"/>
      <geometry>
        <mesh filename="package://nao_detector/meshes/V32/LAnklePitch.mesh" scale="0.001 0.001 0.001"/>
      </geometry>
      <material name="LightGrey"/>
    </collision>
  </link>
  <link name="LAnkleRoll_link">
    <visual>
      <origin xyz="0 0 0" rpy="0 -0 0"/>
      <geometry>
        <mesh filename="package://nao_detector/meshes/V32/LAnkleRoll.mesh" scale="0.001 0.001 0.001"/>
      </geometry>
      <material name="LightGrey"/>
    </visual>
    <inertial>
      <origin xyz="-0.03208 -0.0033 0.02489" rpy="0 0 0"/>
      <mass value="0.16304"/>
      <inertia ixx="0.000267598" ixy="-5.92718e-06" ixz="0.000137299" iyy="0.000643148" iyz="1.86977e-05" izz="0.000526497" />
    </inertial>
    <collision>
      <origin xyz="0 0 0" rpy="0 -0 0"/>
      <geometry>
        <mesh filename="package://nao_detector/meshes/V32/LAnkleRoll.mesh" scale="0.001 0.001 0.001"/>
      </geometry>
      <material name="LightGrey"/>
    </collision>
  </link>
  <link name="RHipYawPitch_link">
    <visual>
      <origin xyz="0 0 0" rpy="0 -0 0"/>
      <geometry>
        <mesh filename="package://nao_detector/meshes/V32/RHipYawPitch.mesh" scale="0.001 0.001 0.001"/>
      </geometry>
      <material name="LightGrey"/>
    </visual>
    <inertial>
      <origin xyz="0.0107339 -0.00717 0.0275206" rpy="0 0 0"/>
      <mass value="0.07244"/>
      <inertia ixx="9.06449e-05" ixy="4.88819e-06" ixz="1.22192e-05" iyy="0.000106658" iyz="-2.78382e-05" izz="6.74286e-05" />
    </inertial>
    <collision>
      <origin xyz="0 0 0" rpy="0 -0 0"/>
      <geometry>
        <mesh filename="package://nao_detector/meshes/V32/RHipYawPitch.mesh" scale="0.001 0.001 0.001"/>
      </geometry>
      <material name="LightGrey"/>
    </collision>
  </link>
  <link name="RHipRoll_link">
    <visual>
      <origin xyz="0 0 0" rpy="0 -0 0"/>
      <geometry>
        <mesh filename="package://nao_detector/meshes/V32/RHipRoll.mesh" scale="0.001 0.001 0.001"/>
      </geometry>
      <material name="LightGrey"/>
    </visual>
    <inertial>
      <origin xyz="-0.00475 0.00029 -0.01649" rpy="0 0 0"/>
      <mass value="0.1353"/>
      <inertia ixx="2.79131e-05" ixy="-4.982e-08" ixz="-5.30968e-06" iyy="0.000101469" iyz="-4.9e-10" izz="0.000292094" />
    </inertial>
    <collision>
      <origin xyz="0 0 0" rpy="0 -0 0"/>
      <geometry>
        <mesh filename="package://nao_detector/meshes/V32/RHipRoll.mesh" scale="0.001 0.001 0.001"/>
      </geometry>
      <material name="LightGrey"/>
    </collision>
  </link>
  <link name="RHipPitch_link">
    <visual>
      <origin xyz="0 0 0" rpy="0 -0 0"/>
      <geometry>
        <mesh filename="package://nao_detector/meshes/V32/RHipPitch.mesh" scale="0.001 0.001 0.001"/>
      </geometry>
      <material name="LightGrey"/>
    </visual>
    <inertial>
      <origin xyz="-0.05386 0.00131 -0.00201" rpy="0 0 0"/>
      <mass value="0.39798"/>
      <inertia ixx="0.00166559" ixy="-4.3251e-07" ixz="8.25051e-05" iyy="0.001625" iyz="-3.17428e-05" izz="0.000304929" />
    </inertial>
    <collision>
      <origin xyz="0 0 0" rpy="0 -0 0"/>
      <geometry>
        <mesh filename="package://nao_detector/meshes/V32/RHipPitch.mesh" scale="0.001 0.001 0.001"/>
      </geometry>
      <material name="LightGrey"/>
    </collision>
  </link>
  <link name="RKneePitch_link">
    <visual>
      <origin xyz="0 0 0" rpy="0 -0 0"/>
      <geometry>
        <mesh filename="package://nao_detector/meshes/V32/RKneePitch.mesh" scale="0.001 0.001 0.001"/>
      </geometry>
      <material name="LightGrey"/>
    </visual>
    <inertial>
      <origin xyz="-0.04891 0.00471 -0.0021" rpy="0 0 0"/>
      <mass value="0.29714"/>
      <inertia ixx="0.00118034" ixy="-3.0542e-07" ixz="4.0171e-05" iyy="0.00112928" iyz="-3.57364e-05" izz="0.00019349" />
    </inertial>
    <collision>
      <origin xyz="0 0 0" rpy="0 -0 0"/>
      <geometry>
        <mesh filename="package://nao_detector/meshes/V32/RKneePitch.mesh" scale="0.001 0.001 0.001"/>
      </geometry>
      <material name="LightGrey"/>
    </collision>
  </link>
  <link name="RAnklePitch_link">
    <visual>
      <origin xyz="0 0 0" rpy="0 -0 0"/>
      <geometry>
        <mesh filename="package://nao_detector/meshes/V32/RAnklePitch.mesh" scale="0.001 0.001 0.001"/>
      </geometry>
      <material name="LightGrey"/>
    </visual>
    <inertial>
      <origin xyz="0.00638 0.00142 -0.00028" rpy="0 0 0"/>
      <mass value="0.13892"/>
      <inertia ixx="3.88258e-05" ixy="4.942e-08" ixz="2.21321e-06" iyy="7.21158e-05" iyz="-6.74e-09" izz="5.35199e-05" />
    </inertial>
    <collision>
      <origin xyz="0 0 0" rpy="0 -0 0"/>
      <geometry>
        <mesh filename="package://nao_detector/meshes/V32/RAnklePitch.mesh" scale="0.001 0.001 0.001"/>
      </geometry>
      <material name="LightGrey"/>
    </collision>
  </link>
  <link name="RAnkleRoll_link">
    <visual>
      <origin xyz="0 0 0" rpy="0 -0 0"/>
      <geometry>
        <mesh filename="package://nao_detector/meshes/V32/RAnkleRoll.mesh" scale="0.001 0.001 0.001"/>
      </geometry>
      <material name="LightGrey"/>
    </visual>
    <inertial>
      <origin xyz="-0.03208 0.0033 0.02489" rpy="0 0 0"/>
      <mass value="0.16304"/>
      <inertia ixx="0.000267598" ixy="5.92718e-06" ixz="1.37299e-05" iyy="0.000643148" iyz="-1.86977e-05" izz="0.000526497" />
    </inertial>
    <collision>
      <origin xyz="0 0 0" rpy="0 -0 0"/>
      <geometry>
        <mesh filename="package://nao_detector/meshes/V32/RAnkleRoll.mesh" scale="0.001 0.001 0.001"/>
      </geometry>
      <material name="LightGrey"/>
    </collision>
  </link>

  <joint name="HeadYaw" type="continuous">
    <parent link="torso"/>
    <child link="HeadYaw_link"/>
    <origin xyz="0 0 0.1265" rpy="0 -0 0"/>
    <axis xyz="0 0 1"/>
  </joint>
  <joint name="HeadPitch" type="continuous">
    <parent link="HeadYaw_link"/>
    <child link="HeadPitch_link"/>
    <origin xyz="0 0 0" rpy="0 -0 0"/>
    <axis xyz="0 1 0"/>
  </joint>
  <joint name="LShoulderPitch" type="continuous">
    <parent link="torso"/>
    <child link="LShoulderPitch_link"/>
    <origin xyz="0 0.098 0.1" rpy="0 -0 0"/>
    <axis xyz="0 1 0"/>
  </joint>
  <joint name="LShoulderRoll" type="continuous">
    <parent link="LShoulderPitch_link"/>
    <child link="LShoulderRoll_link"/>
    <origin xyz="0 0 0" rpy="0 -0 0"/>
    <axis xyz="0 0 1"/>
  </joint>
  <joint name="LElbowYaw" type="continuous">
    <parent link="LShoulderRoll_link"/>
    <child link="LElbowYaw_link"/>
    <origin xyz="0.09 0 0" rpy="0 -0 0"/>
    <axis xyz="1 0 0"/>
  </joint>
  <joint name="LElbowRoll" type="continuous">
    <parent link="LElbowYaw_link"/>
    <child link="LElbowRoll_link"/>
    <origin xyz="0 0 0" rpy="0 -0 0"/>
    <axis xyz="0 0 1"/>
  </joint>
  <joint name="LWristYaw" type="continuous">
    <parent link="LElbowRoll_link"/>
    <child link="LWristYaw_link"/>
    <origin xyz="0.05055 0 0" rpy="0 -0 0"/>
    <axis xyz="1 0 0"/>
  </joint>
  
  
  <joint name="RShoulderPitch" type="continuous">
    <parent link="torso"/>
    <child link="RShoulderPitch_link"/>
    <origin xyz="0 -0.098 0.1" rpy="0 -0 0"/>
    <axis xyz="0 1 0"/>
  </joint>
  <joint name="RShoulderRoll" type="continuous">
    <parent link="RShoulderPitch_link"/>
    <child link="RShoulderRoll_link"/>
    <origin xyz="0 0 0" rpy="0 -0 0"/>
    <axis xyz="0 0 1"/>
  </joint>
  <joint name="RElbowYaw" type="continuous">
    <parent link="RShoulderRoll_link"/>
    <child link="RElbowYaw_link"/>
    <origin xyz="0.09 0 0" rpy="0 -0 0"/>
    <axis xyz="1 0 0"/>
  </joint>
  <joint name="RElbowRoll" type="continuous">
    <parent link="RElbowYaw_link"/>
    <child link="RElbowRoll_link"/>
    <origin xyz="0 0 0" rpy="0 -0 0"/>
    <axis xyz="0 0 1"/>
  </joint>
  <joint name="RWristYaw" type="continuous">
    <parent link="RElbowRoll_link"/>
    <child link="RWristYaw_link"/>
    <origin xyz="0.05055 0 0" rpy="0 -0 0"/>
    <axis xyz="1 0 0"/>
  </joint>
  
  <joint name="LHipYawPitch" type="continuous">
    <parent link="torso"/>
    <child link="LHipYawPitch_link"/>
    <origin xyz="0 0.05 -0.085" rpy="0 -0 0"/>
    <axis xyz="0 0.707107 -0.707107"/>
  </joint>
  <joint name="LHipRoll" type="continuous">
    <parent link="LHipYawPitch_link"/>
    <child link="LHipRoll_link"/>
    <origin xyz="0 0 0" rpy="0 -0 0"/>
    <axis xyz="1 0 0"/>
  </joint>
  <joint name="LHipPitch" type="continuous">
    <parent link="LHipRoll_link"/>
    <child link="LHipPitch_link"/>
    <origin xyz="0 0 0" rpy="0 -0 0"/>
    <axis xyz="0 1 0"/>
  </joint>
  <joint name="LKneePitch" type="continuous">
    <parent link="LHipPitch_link"/>
    <child link="LKneePitch_link"/>
    <origin xyz="0 0 -0.1" rpy="0 -0 0"/>
    <axis xyz="0 1 0"/>
  </joint>
  <joint name="LAnklePitch" type="continuous">
    <parent link="LKneePitch_link"/>
    <child link="LAnklePitch_link"/>
    <origin xyz="0 0 -0.1029" rpy="0 -0 0"/>
    <axis xyz="0 1 0"/>
  </joint>
  <joint name="LAnkleRoll" type="continuous">
    <parent link="LAnklePitch_link"/>
    <child link="LAnkleRoll_link"/>
    <origin xyz="0 0 0" rpy="0 -0 0"/>
    <axis xyz="1 0 0"/>
  </joint>
  <joint name="RHipYawPitch" type="continuous">
    <parent link="torso"/>
    <child link="RHipYawPitch_link"/>
    <origin xyz="0 -0.05 -0.085" rpy="0 -0 0"/>
    <axis xyz="0 0.707107 0.707107"/>
  </joint>
  <joint name="RHipRoll" type="continuous">
    <parent link="RHipYawPitch_link"/>
    <child link="RHipRoll_link"/>
    <origin xyz="0 0 0" rpy="0 -0 0"/>
    <axis xyz="1 0 0"/>
  </joint>
  <joint name="RHipPitch" type="continuous">
    <parent link="RHipRoll_link"/>
    <child link="RHipPitch_link"/>
    <origin xyz="0 0 0" rpy="0 -0 0"/>
    <axis xyz="0 1 0"/>
  </joint>
  <joint name="RKneePitch" type="continuous">
    <parent link="RHipPitch_link"/>
    <child link="RKneePitch_link"/>
    <origin xyz="0 0 -0.1" rpy="0 -0 0"/>
    <axis xyz="0 1 0"/>
  </joint>
  <joint name="RAnklePitch" type="continuous">
    <parent link="RKneePitch_link"/>
    <child link="RAnklePitch_link"/>
    <origin xyz="0 0 -0.1029" rpy="0 -0 0"/>
    <axis xyz="0 1 0"/>
  </joint>
  <joint name="RAnkleRoll" type="continuous">
    <parent link="RAnklePitch_link"/>
    <child link="RAnkleRoll_link"/>
    <origin xyz="0 0 0" rpy="0 -0 0"/>
    <axis xyz="1 0 0"/>
  </joint>
  <joint name="base_joint" type="fixed">
    <child link="torso"/>
    <parent link="base_link"/>
    <origin rpy="0 0 0" xyz="0 0 0"/>
  </joint>
</robot>
